[2022-07-14 14:06:21,520] {taskinstance.py:1159} INFO - Dependencies all met for <TaskInstance: user_processing.process_user manual__2022-07-14T14:06:19.764023+00:00 [queued]>
[2022-07-14 14:06:21,532] {taskinstance.py:1159} INFO - Dependencies all met for <TaskInstance: user_processing.process_user manual__2022-07-14T14:06:19.764023+00:00 [queued]>
[2022-07-14 14:06:21,533] {taskinstance.py:1356} INFO - 
--------------------------------------------------------------------------------
[2022-07-14 14:06:21,534] {taskinstance.py:1357} INFO - Starting attempt 1 of 1
[2022-07-14 14:06:21,535] {taskinstance.py:1358} INFO - 
--------------------------------------------------------------------------------
[2022-07-14 14:06:21,552] {taskinstance.py:1377} INFO - Executing <Task(PythonOperator): process_user> on 2022-07-14 14:06:19.764023+00:00
[2022-07-14 14:06:21,560] {standard_task_runner.py:52} INFO - Started process 8103 to run task
[2022-07-14 14:06:21,564] {standard_task_runner.py:79} INFO - Running: ['***', 'tasks', 'run', 'user_processing', 'process_user', 'manual__2022-07-14T14:06:19.764023+00:00', '--job-id', '23', '--raw', '--subdir', 'DAGS_FOLDER/user_processing.py', '--cfg-path', '/tmp/tmpk1by2hv_', '--error-file', '/tmp/tmpa20m_m02']
[2022-07-14 14:06:21,567] {standard_task_runner.py:80} INFO - Job 23: Subtask process_user
[2022-07-14 14:06:21,662] {task_command.py:369} INFO - Running <TaskInstance: user_processing.process_user manual__2022-07-14T14:06:19.764023+00:00 [running]> on host 9d087153d2d5
[2022-07-14 14:06:21,734] {taskinstance.py:1571} INFO - Exporting the following env vars:
AIRFLOW_CTX_DAG_OWNER=***
AIRFLOW_CTX_DAG_ID=user_processing
AIRFLOW_CTX_TASK_ID=process_user
AIRFLOW_CTX_EXECUTION_DATE=2022-07-14T14:06:19.764023+00:00
AIRFLOW_CTX_TRY_NUMBER=1
AIRFLOW_CTX_DAG_RUN_ID=manual__2022-07-14T14:06:19.764023+00:00
[2022-07-14 14:06:21,748] {taskinstance.py:1889} ERROR - Task failed with exception
Traceback (most recent call last):
  File "/home/airflow/.local/lib/python3.7/site-packages/airflow/operators/python.py", line 171, in execute
    return_value = self.execute_callable()
  File "/home/airflow/.local/lib/python3.7/site-packages/airflow/operators/python.py", line 189, in execute_callable
    return self.python_callable(*self.op_args, **self.op_kwargs)
  File "/opt/airflow/dags/user_processing.py", line 14, in _process_user
    user = user['results'][0]
TypeError: 'NoneType' object is not subscriptable
[2022-07-14 14:06:21,765] {taskinstance.py:1400} INFO - Marking task as FAILED. dag_id=user_processing, task_id=process_user, execution_date=20220714T140619, start_date=20220714T140621, end_date=20220714T140621
[2022-07-14 14:06:21,776] {standard_task_runner.py:97} ERROR - Failed to execute job 23 for task process_user ('NoneType' object is not subscriptable; 8103)
[2022-07-14 14:06:21,823] {local_task_job.py:156} INFO - Task exited with return code 1
[2022-07-14 14:06:21,916] {local_task_job.py:273} INFO - 0 downstream tasks scheduled from follow-on schedule check
