[2022-07-21 17:38:21,793] {taskinstance.py:1159} INFO - Dependencies all met for <TaskInstance: user_processing.process_user manual__2022-07-21T17:38:19.421407+00:00 [queued]>
[2022-07-21 17:38:21,809] {taskinstance.py:1159} INFO - Dependencies all met for <TaskInstance: user_processing.process_user manual__2022-07-21T17:38:19.421407+00:00 [queued]>
[2022-07-21 17:38:21,810] {taskinstance.py:1356} INFO - 
--------------------------------------------------------------------------------
[2022-07-21 17:38:21,814] {taskinstance.py:1357} INFO - Starting attempt 1 of 1
[2022-07-21 17:38:21,815] {taskinstance.py:1358} INFO - 
--------------------------------------------------------------------------------
[2022-07-21 17:38:21,833] {taskinstance.py:1377} INFO - Executing <Task(PythonOperator): process_user> on 2022-07-21 17:38:19.421407+00:00
[2022-07-21 17:38:21,845] {standard_task_runner.py:52} INFO - Started process 7992 to run task
[2022-07-21 17:38:21,858] {standard_task_runner.py:79} INFO - Running: ['***', 'tasks', 'run', 'user_processing', 'process_user', 'manual__2022-07-21T17:38:19.421407+00:00', '--job-id', '100', '--raw', '--subdir', 'DAGS_FOLDER/user_processing.py', '--cfg-path', '/tmp/tmpj60_0ky1', '--error-file', '/tmp/tmpb_dy7b_x']
[2022-07-21 17:38:21,863] {standard_task_runner.py:80} INFO - Job 100: Subtask process_user
[2022-07-21 17:38:21,963] {task_command.py:369} INFO - Running <TaskInstance: user_processing.process_user manual__2022-07-21T17:38:19.421407+00:00 [running]> on host e755cbaa46dc
[2022-07-21 17:38:22,085] {taskinstance.py:1571} INFO - Exporting the following env vars:
AIRFLOW_CTX_DAG_OWNER=***
AIRFLOW_CTX_DAG_ID=user_processing
AIRFLOW_CTX_TASK_ID=process_user
AIRFLOW_CTX_EXECUTION_DATE=2022-07-21T17:38:19.421407+00:00
AIRFLOW_CTX_TRY_NUMBER=1
AIRFLOW_CTX_DAG_RUN_ID=manual__2022-07-21T17:38:19.421407+00:00
[2022-07-21 17:38:22,104] {taskinstance.py:1889} ERROR - Task failed with exception
Traceback (most recent call last):
  File "/home/airflow/.local/lib/python3.7/site-packages/airflow/operators/python.py", line 171, in execute
    return_value = self.execute_callable()
  File "/home/airflow/.local/lib/python3.7/site-packages/airflow/operators/python.py", line 189, in execute_callable
    return self.python_callable(*self.op_args, **self.op_kwargs)
  File "/opt/airflow/dags/user_processing.py", line 17, in _process_user
    user = user['results'][0]
TypeError: 'NoneType' object is not subscriptable
[2022-07-21 17:38:22,123] {taskinstance.py:1400} INFO - Marking task as FAILED. dag_id=user_processing, task_id=process_user, execution_date=20220721T173819, start_date=20220721T173821, end_date=20220721T173822
[2022-07-21 17:38:22,154] {standard_task_runner.py:97} ERROR - Failed to execute job 100 for task process_user ('NoneType' object is not subscriptable; 7992)
[2022-07-21 17:38:22,196] {local_task_job.py:156} INFO - Task exited with return code 1
[2022-07-21 17:38:22,265] {local_task_job.py:273} INFO - 0 downstream tasks scheduled from follow-on schedule check
