[2022-07-21 17:39:52,177] {taskinstance.py:1159} INFO - Dependencies all met for <TaskInstance: user_processing.process_user manual__2022-07-21T17:39:50.548594+00:00 [queued]>
[2022-07-21 17:39:52,186] {taskinstance.py:1159} INFO - Dependencies all met for <TaskInstance: user_processing.process_user manual__2022-07-21T17:39:50.548594+00:00 [queued]>
[2022-07-21 17:39:52,188] {taskinstance.py:1356} INFO - 
--------------------------------------------------------------------------------
[2022-07-21 17:39:52,190] {taskinstance.py:1357} INFO - Starting attempt 1 of 1
[2022-07-21 17:39:52,191] {taskinstance.py:1358} INFO - 
--------------------------------------------------------------------------------
[2022-07-21 17:39:52,203] {taskinstance.py:1377} INFO - Executing <Task(PythonOperator): process_user> on 2022-07-21 17:39:50.548594+00:00
[2022-07-21 17:39:52,210] {standard_task_runner.py:52} INFO - Started process 8089 to run task
[2022-07-21 17:39:52,215] {standard_task_runner.py:79} INFO - Running: ['***', 'tasks', 'run', 'user_processing', 'process_user', 'manual__2022-07-21T17:39:50.548594+00:00', '--job-id', '106', '--raw', '--subdir', 'DAGS_FOLDER/user_processing.py', '--cfg-path', '/tmp/tmp1yt1ugik', '--error-file', '/tmp/tmppu5g758t']
[2022-07-21 17:39:52,222] {standard_task_runner.py:80} INFO - Job 106: Subtask process_user
[2022-07-21 17:39:52,315] {task_command.py:369} INFO - Running <TaskInstance: user_processing.process_user manual__2022-07-21T17:39:50.548594+00:00 [running]> on host e755cbaa46dc
[2022-07-21 17:39:52,394] {taskinstance.py:1571} INFO - Exporting the following env vars:
AIRFLOW_CTX_DAG_OWNER=***
AIRFLOW_CTX_DAG_ID=user_processing
AIRFLOW_CTX_TASK_ID=process_user
AIRFLOW_CTX_EXECUTION_DATE=2022-07-21T17:39:50.548594+00:00
AIRFLOW_CTX_TRY_NUMBER=1
AIRFLOW_CTX_DAG_RUN_ID=manual__2022-07-21T17:39:50.548594+00:00
[2022-07-21 17:39:52,409] {taskinstance.py:1889} ERROR - Task failed with exception
Traceback (most recent call last):
  File "/home/airflow/.local/lib/python3.7/site-packages/airflow/operators/python.py", line 171, in execute
    return_value = self.execute_callable()
  File "/home/airflow/.local/lib/python3.7/site-packages/airflow/operators/python.py", line 189, in execute_callable
    return self.python_callable(*self.op_args, **self.op_kwargs)
  File "/opt/airflow/dags/user_processing.py", line 17, in _process_user
    user = user['results'][0]
TypeError: 'NoneType' object is not subscriptable
[2022-07-21 17:39:52,428] {taskinstance.py:1400} INFO - Marking task as FAILED. dag_id=user_processing, task_id=process_user, execution_date=20220721T173950, start_date=20220721T173952, end_date=20220721T173952
[2022-07-21 17:39:52,440] {standard_task_runner.py:97} ERROR - Failed to execute job 106 for task process_user ('NoneType' object is not subscriptable; 8089)
[2022-07-21 17:39:52,471] {local_task_job.py:156} INFO - Task exited with return code 1
[2022-07-21 17:39:52,502] {local_task_job.py:273} INFO - 0 downstream tasks scheduled from follow-on schedule check
